<?xml version="1.0" ?>
<!-- =================================================================================== -->
<!-- |    This document was autogenerated by xacro from /home/joep/foxy_personal_ws/install/robot_manipulator/share/robot_manipulator/urdf/robot_manipulator.urdf.xacro | -->
<!-- |    EDITING THIS FILE BY HAND IS NOT RECOMMENDED                                 | -->
<!-- =================================================================================== -->
<robot name="robot_manipulator">
  <link name="base_footprint"/>
  <joint name="base_joint" type="fixed">
    <parent link="base_footprint"/>
    <child link="base_link"/>
    <origin rpy="0 0 0" xyz="0 0 0.1"/>
  </joint>
  <link name="base_link">
    <visual>
      <origin rpy="0 0 0" xyz="0 0 0"/>
      <geometry>
        <cylinder length="0.15" radius="0.25"/>
      </geometry>
      <material name="red">
        <color rgba="0.8 0.0 0.0 1.0"/>
      </material>
    </visual>
    <collision>
      <origin rpy="0 0 0" xyz="0 0 0"/>
      <geometry>
        <cylinder length="0.15" radius="0.2"/>
      </geometry>
    </collision>
    <inertial>
      <mass value="15.0"/>
      <origin xyz="0.0 0 0.0"/>
      <inertia ixx="2.3" ixy="0.0" ixz="0.0" iyy="1.0" iyz="0.0" izz="1.5"/>
    </inertial>
  </link>
  <gazebo reference="base_link">
    <selfCollide>false</selfCollide>
    <material value="Gazebo/Red"/>
    <turnGravityOff>false</turnGravityOff>
  </gazebo>
  <joint name="caster_back_joint" type="fixed">
    <parent link="base_link"/>
    <child link="caster_back_link"/>
    <origin rpy="0 0 0" xyz="-0.23 0 -0.088"/>
  </joint>
  <link name="caster_back_link">
    <visual>
      <geometry>
        <sphere radius="0.01"/>
      </geometry>
    </visual>
    <collision>
      <geometry>
        <sphere radius="0.01"/>
      </geometry>
    </collision>
    <inertial>
      <mass value="0.001"/>
      <origin xyz="0.0 0 0.0"/>
      <inertia ixx="0.00001" ixy="0.0" ixz="0.0" iyy="0.00001" iyz="0.0" izz="0.00001"/>
    </inertial>
  </link>
  <gazebo reference="caster_back_link">
    <material>Gazebo/Black</material>
    <turnGravityOff>false</turnGravityOff>
  </gazebo>
  <joint name="caster_front_joint" type="fixed">
    <parent link="base_link"/>
    <child link="caster_front_link"/>
    <origin rpy="0 0 0" xyz="0.23 0 -0.088"/>
  </joint>
  <link name="caster_front_link">
    <visual>
      <geometry>
        <sphere radius="0.01"/>
      </geometry>
    </visual>
    <collision>
      <geometry>
        <sphere radius="0.01"/>
      </geometry>
    </collision>
    <inertial>
      <mass value="0.001"/>
      <origin xyz="0.0 0 0.0"/>
      <inertia ixx="0.00001" ixy="0.0" ixz="0.0" iyy="0.00001" iyz="0.0" izz="0.00001"/>
    </inertial>
  </link>
  <gazebo reference="caster_front_link">
    <material>Gazebo/Black</material>
    <turnGravityOff>false</turnGravityOff>
  </gazebo>
  <link name="wheel_left">
    <visual>
      <origin rpy="1.570796327 0 0" xyz="0 0 0"/>
      <geometry>
        <cylinder length="0.06" radius="0.06"/>
      </geometry>
      <material name="black"/>
    </visual>
    <collision>
      <origin rpy="1.570796327 0 0" xyz="0 0 0"/>
      <geometry>
        <cylinder length="0.06" radius="0.06"/>
      </geometry>
    </collision>
    <inertial>
      <mass value="1.5"/>
      <origin xyz="0 0 0"/>
      <inertia ixx="0.0018000000000000002" ixy="0" ixz="0" iyy="0.0018000000000000002" iyz="0" izz="0.0026999999999999997"/>
    </inertial>
  </link>
  <gazebo reference="wheel_left">
    <material>Gazebo/Black</material>
    <turnGravityOff>false</turnGravityOff>
    <collision name="wheel_left_collision">
      <surface>
        <contact>
          <ode>
            <soft_cfm>0</soft_cfm>
            <soft_erp>0.2</soft_erp>
            <kp>100000</kp>
            <kd>0.1</kd>
            <max_vel>20</max_vel>
            <min_depth>0.001</min_depth>
          </ode>
        </contact>
      </surface>
    </collision>
  </gazebo>
  <joint name="wheel_left_joint" type="revolute">
    <parent link="base_link"/>
    <child link="wheel_left"/>
    <origin rpy="0 0 0" xyz="0 0.2 -0.04"/>
    <axis xyz="0 1 0"/>
    <limit effort="20.0" lower="-1e+16" upper="1e+16" velocity="5.0"/>
    <dynamics damping="0.4" friction="0.2"/>
  </joint>
  <link name="wheel_right">
    <visual>
      <origin rpy="1.570796327 0 0" xyz="0 0 0"/>
      <geometry>
        <cylinder length="0.06" radius="0.06"/>
      </geometry>
      <material name="black"/>
    </visual>
    <collision>
      <origin rpy="1.570796327 0 0" xyz="0 0 0"/>
      <geometry>
        <cylinder length="0.06" radius="0.06"/>
      </geometry>
    </collision>
    <inertial>
      <mass value="1.5"/>
      <origin xyz="0 0 0"/>
      <inertia ixx="0.0018000000000000002" ixy="0" ixz="0" iyy="0.0018000000000000002" iyz="0" izz="0.0026999999999999997"/>
    </inertial>
  </link>
  <gazebo reference="wheel_right">
    <material>Gazebo/Black</material>
    <turnGravityOff>false</turnGravityOff>
    <collision name="wheel_right_collision">
      <surface>
        <contact>
          <ode>
            <soft_cfm>0</soft_cfm>
            <soft_erp>0.2</soft_erp>
            <kp>100000</kp>
            <kd>0.1</kd>
            <max_vel>20</max_vel>
            <min_depth>0.001</min_depth>
          </ode>
        </contact>
      </surface>
    </collision>
  </gazebo>
  <joint name="wheel_right_joint" type="revolute">
    <parent link="base_link"/>
    <child link="wheel_right"/>
    <origin rpy="0 0 0" xyz="0 -0.2 -0.04"/>
    <axis xyz="0 1 0"/>
    <limit effort="20.0" lower="-1e+16" upper="1e+16" velocity="5.0"/>
    <dynamics damping="0.4" friction="0.2"/>
  </joint>
  <gazebo>
    <plugin filename="libgazebo_ros_diff_drive.so" name="base_diff_drive">
      <!-- <ros> tags are needed for nav2_gazebo_spawner -->
      <ros>
      </ros>
      <update_rate>100.0</update_rate>
      <left_joint>wheel_left_joint</left_joint>
      <right_joint>wheel_right_joint</right_joint>
      <wheel_separation>0.4</wheel_separation>
      <wheel_diameter>0.12</wheel_diameter>
      <max_wheel_torque>100</max_wheel_torque>
      <max_wheel_acceleration>200</max_wheel_acceleration>
      <publish_odom>true</publish_odom>
      <publish_odom_tf>true</publish_odom_tf>
      <publish_wheel_tf>false</publish_wheel_tf>
      <odometry_topic>odom</odometry_topic>
      <odometry_frame>odom</odometry_frame>
      <robot_base_frame>base_footprint</robot_base_frame>
    </plugin>
  </gazebo>
  <!-- z_offset: distance between base plate and laser center (= center of mesh) -->
  <link name="lidar_mount_link">
    <inertial>
      <mass value="0.001"/>
      <origin xyz="0 0 0"/>
      <inertia ixx="0.000001" ixy="0.0" ixz="0.0" iyy="0.000001" iyz="0.0" izz="0.000001"/>
    </inertial>
  </link>
  <joint name="lidar_joint" type="fixed">
    <parent link="lidar_mount_link"/>
    <child link="lidar"/>
    <origin rpy="0 0 0" xyz="0 0 0.02"/>
  </joint>
  <link name="lidar">
    <visual>
      <origin xyz="0 0 -0.005"/>
      <geometry>
        <cylinder length="0.03" radius="0.04"/>
      </geometry>
      <material name="blue"/>
    </visual>
    <collision>
      <origin xyz="0 0 -0.005"/>
      <geometry>
        <cylinder length="0.03" radius="0.04"/>
      </geometry>
    </collision>
    <inertial>
      <mass value="0.25"/>
      <origin xyz="0 0 -0.026"/>
      <inertia ixx="0.01548332714" ixy="0.0" ixz="0.0" iyy="0.01548332714" iyz="0.0" izz="0.00014999993999999998"/>
    </inertial>
  </link>
  <joint name="lidar_mount_joint" type="fixed">
    <parent link="base_link"/>
    <child link="lidar_mount_link"/>
    <origin rpy="0 0 0" xyz="0.2 0 0.075"/>
  </joint>
  <gazebo reference="lidar">
    <turnGravityOff>false</turnGravityOff>
    <material value="Gazebo/Blue"/>
    <sensor name="lidar" type="ray">
      <topic>scan</topic>
      <always_on>true</always_on>
      <update_rate>30</update_rate>
      <pose>0 0 0 0 0 0</pose>
      <visualize>true</visualize>
      <ray>
        <scan>
          <horizontal>
            <samples>720</samples>
            <resolution>1</resolution>
            <min_angle>-2.357</min_angle>
            <max_angle>2.357</max_angle>
          </horizontal>
        </scan>
        <range>
          <min>0.05</min>
          <max>4</max>
          <resolution>0.01</resolution>
        </range>
        <noise>
          <type>gaussian</type>
          <mean>0</mean>
          <stddev>0.006</stddev>
        </noise>
      </ray>
      <plugin filename="libgazebo_ros_ray_sensor.so" name="gazebo_ros_lidar_controller">
        <ros>
          <remapping>~/out:=scan</remapping>
        </ros>
        <frame_name>lidar</frame_name>
        <output_type>sensor_msgs/LaserScan</output_type>
      </plugin>
    </sensor>
  </gazebo>
  <gazebo reference="lidar_mount_link">
    <turnGravityOff>false</turnGravityOff>
  </gazebo>
</robot>
